# 八、异常

当编写计算机程序时，通常有可能区分正常的事件过程和异常的事情。这种异常事件可能是错误(比如试图将一个数除以零)，或者只是一些您不希望经常发生的事情。为了处理这样的异常事件，您可以在事件可能发生的任何地方使用条件(例如，让您的程序检查每个除法的分母是否为零)。然而，这不仅效率低、不灵活，而且会使程序难以辨认。您可能会忽略这些异常事件，只希望它们不会发生，但是 Python 提供了一种异常处理机制作为强大的替代方案。

在本章中，你将学习如何创建和引发你自己的异常，以及如何以各种方式处理异常。

## 什么是异常？

为了表示异常情况，Python 使用异常对象。当遇到错误时，它会引发异常。如果没有处理(或捕获)这样的异常对象，程序将终止于所谓的回溯(错误消息)。

```py
>>> 1 / 0
Traceback (most recent call last):
   File "<stdin>", line 1, in ?
ZeroDivisionError: integer division or modulo by zero

```

如果这样的错误消息是您可以使用异常的全部，它们就不会很有趣了。然而，事实是，每个异常都是某个类的一个实例(在本例中是`ZeroDivisionError`)，这些实例可能会以各种方式被引发和捕获，从而允许您捕获错误并对此采取措施，而不是让整个程序失败。

## 让事情出错。。。你的方式

如您所见，当出现问题时，异常会自动引发。在研究如何处理这些异常之前，让我们看看如何自己引发异常，甚至创建自己的异常。

### 加薪声明

要引发异常，可以使用带有参数的`raise`语句，该参数可以是类(应该是`Exception`的子类)或实例。当使用一个类时，一个实例被自动创建这里是一个例子，使用内置的异常类`Exception`:

```py
>>> raise Exception
Traceback (most recent call last):
   File "<stdin>", line 1, in ?
Exception
>>> raise Exception('hyperdrive overload')
Traceback (most recent call last):
   File "<stdin>", line 1, in ?
Exception: hyperdrive overload

```

第一个例子`raise Exception`，引发了一个普通的异常，没有任何关于出错的信息。在前面的例子中，我添加了错误消息`hyperdrive overload`。

许多内置类是可用的。表 [8-1](#Tab1) 描述了一些最重要的。您可以在 Python 库参考中的“内置异常”一节中找到所有这些异常的描述所有这些异常类都可以在您的`raise`语句中使用。

表 8-1。

Some Built-in Exceptions

<colgroup><col> <col></colgroup> 
| 类别名 | 描述 |
| --- | --- |
| `Exception` | 几乎所有异常的基类。 |
| `AttributeError` | 当属性引用或赋值失败时引发。 |
| `OSError` | 当操作系统无法执行任务(例如文件)时引发。有几个特定的子类。 |
| `IndexError` | 对序列使用不存在的索引时引发。`LookupError`的子类。 |
| `KeyError` | 在映射中使用不存在的键时引发。`LookupError`的子类。 |
| `NameError` | 找不到名称(变量)时引发。 |
| `SyntaxError` | 当代码格式错误时引发。 |
| `TypeError` | 当内置操作或函数应用于错误类型的对象时引发。 |
| `ValueError` | 当内置操作或函数应用于类型正确但值不正确的对象时引发。 |
| `ZeroDivisionError` | 当除法或模运算的第二个参数为零时引发。 |

```py
>>> raise ArithmeticError
Traceback (most recent call last):
  File "<stdin>", line 1, in ?
ArithmeticError

```

### 自定义异常类

尽管内置的异常覆盖了很多领域，并且足够用于许多目的，但是有时您可能想要创建自己的异常。例如，在`hyperdrive overload`的例子中，用一个特定的`HyperdriveError`类来表示超空间引擎中的错误情况不是更自然吗？错误消息似乎已经足够了，但是正如您将在下一节(“捕获异常”)中看到的，您可以根据异常的类有选择地处理特定类型的异常。因此，如果您想用特殊的错误处理代码来处理超驱动器错误，您将需要一个单独的异常类。

那么，如何创建异常类呢？就像任何其他类一样——但是一定要子类化`Exception`(直接或间接，这意味着子类化任何其他内置异常都是可以的)。因此，编写一个自定义异常基本上相当于这样的内容:

```py
class SomeCustomException(Exception): pass

```

真的没什么工作量吧？(如果您愿意，当然也可以向异常类添加方法。)

## 捕捉异常

如前所述，异常的有趣之处在于您可以处理它们(通常称为捕获或捕捉异常)。您可以使用`try` / `except`语句来实现这一点。假设您创建了一个程序，让用户输入两个数字，然后用一个除以另一个，如下所示:

```py
x = int(input('Enter the first number: '))
y = int(input('Enter the second number: '))
print(x / y)

```

这将很好地工作，直到用户输入零作为第二个数字。

```py
Enter the first number: 10
Enter the second number: 0
Traceback (most recent call last):
  File "exceptions.py", line 3, in ?
    print(x / y)
ZeroDivisionError: integer division or modulo by zero

```

为了捕捉异常并执行一些错误处理(在这种情况下，只需打印一条更加用户友好的错误消息)，您可以像这样重写程序:

```py
try:
    x = int(input('Enter the first number: '))
    y = int(input('Enter the second number: '))
    print(x / y)
except ZeroDivisionError:
    print("The second number can't be zero!")

```

看起来简单的`if`语句检查`y`的值会更容易使用，在这种情况下，这可能确实是一个更好的解决方案。但是如果你给你的程序增加更多的分部，你将需要每个分部有一个`if`语句；通过使用`try` / `except`，您只需要一个错误处理程序。

Note

异常从函数传播到它们被调用的地方，如果它们也没有被捕获，异常将“冒泡”到程序的顶层。这意味着您可以使用`try` / `except`来捕捉在其他人的函数中引发的异常。有关详细信息，请参阅本章后面的“异常和功能”一节。

### 听着，妈，别争了！

如果您已经捕获了一个异常，但是您想再次引发它(可以说是传递它)，您可以不带任何参数地调用`raise`。(如果捕捉到异常，也可以显式提供异常，如本章后面的“捕捉对象”一节所述。)

作为这可能有用的一个例子，考虑一个具有“抑制”异常能力的计算器类。如果此行为被打开，计算器将打印出一条错误消息，而不是让异常传播。如果计算器在与用户的交互会话中使用，这是很有用的，但是如果在程序内部使用，引发一个异常会更好。因此，可以关闭消声。下面是这样一个类的代码:

```py
class MuffledCalculator:
    muffled = False
    def calc(self, expr):
        try:
            return eval(expr)
        except ZeroDivisionError:
            if self.muffled:
                print('Division by zero is illegal')
            else:
                raise

```

Note

如果出现被零除的情况并且消音被打开，`calc`方法将(隐式地)返回 None。换句话说，如果打开消音，就不应该依赖返回值。

以下是如何使用该等级的示例，包括带消声和不带消声两种情况:

```py
>>> calculator = MuffledCalculator()
>>> calculator.calc('10 / 2')
5.0
>>> calculator.calc('10 / 0') # No muffling
Traceback (most recent call last): File "<stdin>", line 1, in ?
  File "MuffledCalculator.py", line 6, in calc
     return eval(expr)
  File "<string>", line 0, in ?
ZeroDivisionError: integer division or modulo by zero
>>> calculator.muffled = True
>>> calculator.calc('10 / 0')
Division by zero is illegal

```

如你所见，当计算器没有被关闭时，`ZeroDivisionError`被捕获但被传递。

如果您无法处理异常，在`except`子句中使用不带参数的`raise`通常是一个不错的选择。不过，有时您可能想引发一个不同的异常。在这种情况下，导致您进入`except`原因的异常将被存储为您的异常的上下文，并将成为最终错误消息的一部分，例如:

```py
>>> try:
...     1/0
... except ZeroDivisionError:
...     raise ValueError
...
Traceback (most recent call last):
  File "<stdin>", line 2, in <module>
ZeroDivisionError: division by zero

During handling of the above exception, another exception occurred:

Traceback (most recent call last):
  File "<stdin>", line 4, in <module>
ValueError

```

您可以使用语句的`raise ... from ...`版本来提供自己的上下文异常，或者使用`None`来取消上下文。

```py
>>> try:
...     1/0
... except ZeroDivisionError:
...     raise ValueError from None
...
Traceback (most recent call last):
  File "<stdin>", line 4, in <module>
ValueError

```

### 不止一个 except 子句

如果您再次运行上一节中的程序，并在提示符下输入一个非数字值，则会发生另一个异常。

```py
Enter the first number: 10
Enter the second number: "Hello, world!"
Traceback (most recent call last):
  File "exceptions.py", line 4, in ?
     print(x / y)
TypeError: unsupported operand type(s) for /: 'int' and 'str'

```

因为`except`子句只寻找`ZeroDivisionError`异常，所以这一个会溜走并中止程序。为了捕捉这个异常，您可以简单地在同一个`try` / `except`语句中添加另一个`except`子句。

```py
try:
   x = int(input('Enter the first number: '))
   y = int(input('Enter the second number: '))
   print(x / y)
except ZeroDivisionError:
   print("The second number can't be zero!")
except TypeError:
   print("That wasn't a number, was it?")

```

这一次使用`if`语句会更加困难。如何检查一个值是否可以用于除法？有很多方法，但是到目前为止，实际上最好的方法是简单地将这些值相除，看看是否可行。

还要注意异常处理并没有弄乱原始代码。添加大量的`if`语句来检查可能的错误条件很容易使代码变得难以阅读。

### 用一个块捕获两个异常

如果希望用一个块捕获多个异常类型，可以在一个元组中指定它们，如下所示:

```py
try:
   x = int(input('Enter the first number: '))
   y = int(input('Enter the second number: '))
   print(x / y)
except (ZeroDivisionError, TypeError, NameError):
   print('Your numbers were bogus ...')

```

在前面的代码中，如果用户输入字符串或数字以外的内容，或者如果第二个数字是零，则打印相同的错误信息。当然，简单地打印一条错误消息并没有多大帮助。另一种选择是继续询问数字，直到除法运算成功。我将在本章后面的“一切顺利时”一节中向您展示如何做到这一点。

请注意，`except`子句中异常的括号非常重要。一个常见的错误是省略这些括号，在这种情况下，您可能会得到与您想要的不同的结果。有关解释，请参见下一节“捕捉对象”

### 抓住物体

如果您想在一个`except`子句中访问异常对象本身，您可以使用两个参数而不是一个。(注意，即使在捕捉多个异常时，您也只为`except`提供了一个参数——一个元组。)这可能是有用的(例如)，如果你想让你的程序继续运行，但你想以某种方式记录错误(也许只是打印出来给用户)。下面是一个示例程序，它打印出异常(如果发生的话)但保持运行:

```py
try:
    x = int(input('Enter the first number: '))
    y = int(input('Enter the second number: '))
    print(x / y)
except (ZeroDivisionError, TypeError) as e:
    print(e)

```

这个小程序中的`except`子句再次捕获了两种类型的异常，但是因为您也显式地捕获了对象本身，所以您可以将它打印出来，这样用户就可以看到发生了什么。(在本章后面的“当一切都好的时候”一节中，你会看到一个更有用的应用)

### 真正的包罗万象

即使程序处理了几种类型的异常，有些还是会漏掉。比如使用同一个除法程序，只需在提示符下试着按回车键，不用写任何东西。您应该得到一条错误消息和一些关于出错原因的信息(堆栈跟踪)，如下所示:

```py
Traceback (most recent call last):
  ...
ValueError: invalid literal for int() with base 10: ''

```

这个异常通过了`try` / `except`语句——这是正确的。你没有预见到这种情况会发生，也没有为此做好准备。在这些情况下，最好是程序立即崩溃(这样你就能看到哪里出了问题),而不是简单地用一个`try` / `except`语句隐藏异常，而这个语句并不是用来捕捉异常的。

然而，如果您确实想捕捉一段代码中的所有异常，您可以简单地从`except`子句中省略异常类。

```py
try:
    x = int(input('Enter the first number: '))
    y = int(input('Enter the second number: '))
    print(x / y)
except:
    print('Something wrong happened ...')

```

现在你可以做任何你想做的事情。

```py
Enter the first number: "This" is *completely* illegal 123
Something wrong happened ...

```

像这样捕捉所有异常是有风险的，因为它会隐藏您没有想到的错误以及您已经准备好的错误。它还将捕获用户试图通过`Ctrl-C`终止执行的行为，以及您调用的函数试图通过`sys.exit`终止执行的行为，等等。在大多数情况下，使用`except Exception as e`可能会更好，并且可能会对异常对象`e`进行一些检查。这将允许那些极少数不属于`Exception`子类的异常漏网。这包括`SystemExit`和`KeyboardInterrupt`，它们是`BaseException`的子类，是`Exception`本身的超类。

### 当一切都好的时候

在某些情况下，除非发生不好的事情，否则执行一段代码是很有用的；与条件句和循环一样，您可以在`try` / `except`语句中添加一个`else`子句。

```py
try:
   print('A simple task')
except:
   print('What? Something went wrong?')
else:
   print('Ah ... It went as planned.')

```

如果运行此命令，您会得到以下输出:

```py
A simple task
Ah ... It went as planned.

```

使用这个`else`子句，您可以实现本章前面“用一个块捕获两个异常”一节中暗示的循环。

```py
while True:
    try:
        x = int(input('Enter the first number: '))
        y = int(input('Enter the second number: '))
        value = x / y
        print('x / y is', value)
    except:
        print('Invalid input. Please try again.')
    else:
        break

```

在这里，只有当没有出现异常时，循环才被中断(通过`else`子句中的`break`语句)。换句话说，只要有错误发生，程序就会不断要求新的输入。以下是一个运行示例:

```py
Enter the first number: 1
Enter the second number: 0
Invalid input. Please try again.
Enter the first number: 'foo'
Enter the second number: 'bar'
Invalid input. Please try again.
Enter the first number: baz
Invalid input. Please try again.
Enter the first number: 10
Enter the second number: 2
x / y is 5

```

如前所述，使用空的`except`子句的一个更好的替代方法是捕获`Exception`类的所有异常(这也将捕获任何子类的所有异常)。你不能 100%确定你能捕捉到所有的东西，因为你的`try` / `except`语句中的代码可能很淘气，使用老式的字符串异常，或者创建一个没有子类`Exception`的自定义异常。然而，如果您使用的是`except Exception`版本，您可以使用本章前面“捕获对象”一节中的技术在您的小除法程序中打印出一个更有指导意义的错误消息。

```py
while True:
    try:
        x = int(input('Enter the first number: '))
        y = int(input('Enter the second number: '))
        value = x / y
        print('x / y is', value)
    except Exception as e:
        print('Invalid input:', e)
        print('Please try again')
    else:
        break

```

以下是运行示例:

```py
Enter the first number: 1
Enter the second number: 0
Invalid input: integer division or modulo by zero
Please try again
Enter the first number: 'x' Enter the second number: 'y'
Invalid input: unsupported operand type(s) for /: 'str' and 'str'
Please try again
Enter the first number: quuux
Invalid input: name 'quuux' is not defined
Please try again
Enter the first number: 10
Enter the second number: 2
x / y is 5

```

### 最后。。。

最后是`finally`条款。在可能出现异常后，您可以用它来做内务处理。它与一个`try`子句相结合。

```py
x = None
try:
    x = 1 / 0
finally:
    print('Cleaning up ...')
    del x

```

在前面的例子中，无论在`try`子句中出现什么异常，都保证会执行`finally`子句。在`try`子句之前初始化`x`的原因是，否则它将不会因为`ZeroDivisionError`而被赋值。当在`finally`子句中对其使用`del`时，这将导致一个异常，您不会捕捉到这个异常。

如果你运行这个，清理会在程序崩溃和烧毁之前进行。

```py
Cleaning up ...
Traceback (most recent call last):
  File "C:\python\div.py", line 4, in ?
     x = 1 / 0
ZeroDivisionError: integer division or modulo by zero

```

虽然使用`del`删除变量是一种相当愚蠢的清理，但是`finally`子句对于关闭文件或网络套接字之类的东西可能非常有用。(你会在第 14 章[中了解到更多。)](14.html)

您还可以在一个语句中组合使用`try`、`except`、`finally`和`else`(或者只使用其中的三个)。

```py
try:
    1 / 0
except NameError:
    print("Unknown variable")
else:
    print("That went well!")
finally:
    print("Cleaning up.")

```

## 异常和功能

异常和函数很自然地一起工作。如果一个异常是在函数内部引发的，并且没有在那里得到处理，它会传播(冒泡)到调用该函数的地方。如果它也不在那里处理，它将继续传播，直到到达主程序(全局范围)，如果那里没有异常处理程序，程序将中止，并返回一个堆栈跟踪。让我们来看一个例子:

```py
>>> def faulty():
...     raise Exception('Something is wrong')
...
>>> def ignore_exception():
...     faulty()
...
>>> def handle_exception():
...     try:
...         faulty()
...     except:
...         print('Exception handled')
...
>>> ignore_exception()
Traceback (most recent call last):
  File '<stdin>', line 1, in ?
  File '<stdin>', line 2, in ignore_exception
  File '<stdin>', line 2, in faulty
Exception: Something is wrong
>>> handle_exception()
Exception handled

```

如您所见，`faulty`中引发的异常通过`faulty`和`ignore_exception`传播，并最终导致堆栈跟踪。类似地，它传播到`handle_exception`，但是在那里用`try` / `except`语句处理。

## 异常的禅

异常处理并不复杂。如果您知道代码的某些部分可能会导致某种异常，并且您不希望程序在这种情况发生时以堆栈跟踪终止，那么您可以根据需要添加必要的`try` / `except`或`try` / `finally`语句(或它们的某种组合)来处理它。

有时，您可以用条件语句完成与异常处理相同的事情，但是条件语句可能会变得不自然，可读性差。另一方面，有些事情看起来像是对`if` / `else`的自然应用，实际上用`try` / `except`可以实现得更好。让我们来看几个例子。

假设您有一个字典，您想打印存储在特定键下的值，如果它在那里的话。如果它不在那里，你不想做任何事情。代码可能是这样的:

```py
def describe_person(person):
    print('Description of', person['name'])
    print('Age:', person['age'])
    if 'occupation' in person:
        print('Occupation:', person['occupation'])

```

如果您为该函数提供一个包含名称 Throatwobbler 红树林和年龄 42(但没有职业)的字典，您将得到以下输出:

```py
Description of Throatwobbler Mangrove
Age: 42

```

如果您添加职业“camper”，您将得到以下输出:

```py
Description of Throatwobbler Mangrove
Age: 42
Occupation: camper

```

代码很直观，但有点低效(尽管这里主要关心的是代码的简单性)。它必须查找键`'occupation'`两次——一次是查看键是否存在(在条件中),一次是获取值(打印出来)。另一个定义如下:

```py
def describe_person(person):
    print('Description of', person['name'])
    print('Age:', person['age'])
    try:
        print('Occupation:', person['occupation'])
    except KeyError: pass

```

这里，该函数简单地假设键`'occupation'`存在。如果您认为正常情况下是这样的，这可以节省一些精力。将获取并打印该值——不需要额外的获取来检查它是否确实存在。如果这个键不存在，就会引发一个`KeyError`异常，这个异常被`except`子句捕获。

您可能还会发现`try` / `except`在检查对象是否具有特定属性时非常有用。比方说，你想检查一个对象是否有一个`write`属性。那么您可以使用这样的代码:

```py
try:
    obj.write
except AttributeError:
    print('The object is not writeable')
else:
    print('The object is writeable')

```

这里的`try`子句只是访问属性，而不对它做任何有用的事情。如果一个`AttributeError`被引发，那么这个对象没有这个属性；否则，它具有属性。这是第 7 章(在“接口和自省”一节)中介绍的`getattr`解决方案的自然替代方案。你更喜欢哪一个在很大程度上取决于你的品味。

请注意，这里的效率增益并不大。(更像是非常非常微小。)一般来说(除非你的程序有性能问题)，你不应该太担心这种优化。关键是在很多情况下，使用`try` / `except`语句比使用`if` / `else`语句更自然(更“Pythonic 化”)，你应该养成尽可能使用它们的习惯。[T5 1T7】](#Fn1)

## 并不都是异常

如果您只是想提供一个警告，说明事情并不完全像它们应该的那样，您可以使用来自`warnings`模块的`warn`函数。

```py
>>> from warnings import warn
>>> warn("I've got a bad feeling about this.")
__main__:1: UserWarning: I've got a bad feeling about this.
>>>

```

该警告只会显示一次。如果你再运行最后一行，什么也不会发生。

使用您的模块的其他代码可以禁止您的警告，或者只禁止特定种类的警告，使用来自同一个模块的`filterwarnings`函数，指定几个可能采取的动作之一，包括`"error"`和`"ignore"`。

```py
>>> from warnings import filterwarnings
>>> filterwarnings("ignore")
>>> warn("Anyone out there?")
>>> filterwarnings("error")
>>> warn("Something is very wrong!")
Traceback (most recent call last):
  File "<stdin>", line 1, in <module>
UserWarning: Something is very wrong!

```

如您所见，引发的异常是`UserWarning`。发出警告时，可以指定不同的异常或警告类别。这个异常应该是`Warning`的子类。如果您将警告转换为错误，将使用您提供的异常，但是您也可以使用它来专门筛选出给定类型的警告。

```py
>>> filterwarnings("error")
>>> warn("This function is really old...", DeprecationWarning)
Traceback (most recent call last):
  File "<stdin>", line 1, in <module>
DeprecationWarning: This function is really old...
>>> filterwarnings("ignore", category=DeprecationWarning)
>>> warn("Another deprecation warning.", DeprecationWarning)
>>> warn("Something else.")
Traceback (most recent call last):
  File "<stdin>", line 1, in <module>
UserWarning: Something else.

```

除了这个基本的用途之外,`warnings`模块还有一些高级的功能。如果你好奇，可以参考图书馆的参考资料。

## 快速总结

本章涵盖的主要主题如下:

*   异常对象:异常情况(比如发生错误时)由异常对象表示。这些可以用几种方式操作，但是如果忽略，它们会终止你的程序。
*   引发异常:可以用`raise`语句引发异常。它接受异常类或异常实例作为其参数。您还可以提供两个参数(一个异常和一个错误消息)。如果在一个`except`子句中不带参数调用`raise`，它会“重新引发”该子句捕获的异常。
*   自定义异常类:您可以通过子类化`Exception`来创建自己的异常类型。
*   捕捉异常:用一个`try`语句的`except`子句捕捉异常。如果没有在`except`子句中指定一个类，所有的异常都会被捕获。通过将类放在一个元组中，可以指定多个类。如果你给`except`两个参数，第二个被绑定到异常对象。在同一个`try` / `except`语句中可以有几个`except`子句，以对不同的异常做出不同的反应。
*   `else`从句:除了`except`之外，你还可以使用`else`从句。如果主`try`程序块中没有出现异常，则执行`else`子句。
*   最后:如果您需要确保某些代码(例如，清理代码)得到执行，无论是否引发异常，您都可以使用`try` / `finally`。这段代码随后被放入`finally`子句中。
*   异常和函数:当您在函数内部引发异常时，它会传播到调用该函数的地方。(方法也一样。)
*   警告:警告类似于异常，但(通常)只是打印出一条错误消息。您可以指定一个警告类别，它是`Warning`的子类。

### 本章的新功能

<colgroup><col> <col></colgroup> 
| 功能 | 描述 |
| --- | --- |
| `warnings.filterwarnings(action, category=Warning, ...)` | 用于过滤掉警告 |
| `warnings.warn(message, category=None)` | 用于发出警告 |

### 什么现在？

虽然你可能认为这一章的内容很特别(原谅我的双关语)，但下一章真的很神奇。嗯，几乎是神奇的。

Footnotes [1](#Fn1_source)

在 Python 中对`try/except`的偏爱通常可以通过少将·格蕾丝·赫柏的智慧之言来解释，“请求原谅比请求许可更容易。”这种简单地尝试做一些事情并处理任何错误的策略，而不是预先做大量的检查，被称为“三思而后行”。